import { Request, Response } from "express";
import { Common } from "../helper/common";
import ServicesModel from "../models/services";

export class Controller {

    async getAll(req: Request, res: Response, next: any) {
        try {
            let page: number = req.query.page ? parseInt(req.query.page as string) : 1;
            let limit: number = req.query.limit ? parseInt(req.query.limit as string) : 10;
            let offset = (page - 1) * limit;

            const results = await ServicesModel().findAndCountAll({
                offset,
                limit
            });
            
            let data = {
                results: results.rows,
                meta: {
                    total: results.count,
                    page
                }
            }

            res.status(200).json({...data});
        } catch (error) {
            new Common().showLogMessage('Error controlado', error, 'error');
            next({
                message: 'Ha ocurrido un error en nuestro sistema, intenta nuevamente',
                error
            });
        }
    }

    async get(req: Request, res: Response, next: any) {
        try {

            const { id } = req.params;
            const reg = await ServicesModel().findByPk(id);

            if(!reg){
                res.status(404).json({
                    message: `No se encuentra el recurso solicitado con el id ${id}`
                })
            }
            
            res.json(reg);

        } catch (error) {
            new Common().showLogMessage('Error controlado', error, 'error');
            next({
                message: 'Ha ocurrido un error en nuestro sistema, intenta nuevamente',
                error
            });
        }
    }

    async add(req: Request, res: Response, next: any) {

        const { body } = req;

        try {
        
            const reg = await ServicesModel().create(body);
            res.json(reg);
        
        } catch (error) {
            new Common().showLogMessage('Error controlado', error, 'error');
            next({
                message: 'Ha ocurrido un error en nuestro sistema, intenta nuevamente',
                error
            });
        }
    }

    async addImage(req: any, res: Response, next: any) {
        var files: any = req.files;

        console.log(files)
        try {
            res.status(200).json({link: process.env.PATH_IMAGE + files.imageService[0].filename})
        } catch (error) {
            new Common().showLogMessage('Error controlado', error, 'error');
            next({
                message: 'Ha ocurrido un error en nuestro sistema, intenta nuevamente',
                error
            });
        }
    }

    async update(req: Request, res: Response, next: any) {

        const { id } = req.params;
        const { body } = req;

        try {

            const reg = await ServicesModel().findByPk(id);
            if( !reg ){
                return res.status(404).json({
                    message: `No se encuentra el recurso solicitado con el id ${id}`
                });
            }

            await reg.update( body, {
                where: {
                    id
                }
            } );

            res.json(reg);
        
        } catch (error) {
            new Common().showLogMessage('Error controlado', error, 'error');
            next({
                message: 'Ha ocurrido un error en nuestro sistema, intenta nuevamente',
                error
            });
        }

    }

    async delete(req: Request, res: Response, next: any) {

        const { id } = req.params;

        try {

            const reg= await ServicesModel().findByPk(id);
            if( !reg ){
                return res.status(404).json({
                    message: `No se encuentra el recurso solicitado con el id ${id}`
                });
            }

            // Eliminaci√≥n fisica
            await reg.destroy();

            res.json({
                message: `El registro con el ID ${id} ha sido eliminado`
            })

        } catch (error) {
            new Common().showLogMessage('Error controlado', error, 'error');
            next({
                message: 'Ha ocurrido un error en nuestro sistema, intenta nuevamente',
                error
            });
        }
    }
}
